<mujoco model="quadruped_body">
<option timestep="0.005"/>

<asset>
  <texture name="body" type="cube" builtin="flat" mark="cross"
           width="128" height="128"
           rgb1="0.8 0.6 0.4" rgb2="0.8 0.6 0.4" markrgb="1 1 1"/>
  <material name="body" texture="body" texuniform="true" rgba="0.8 0.6 .4 1"/>

  <texture name="dark" type="cube" builtin="flat"
           width="128" height="128"
           rgb1="0.1 0.1 0.1" rgb2="0.1 0.1 0.1"/>
  <material name="dark" texture="dark" texuniform="true" rgba="0.1 0.1 0.1 1"/>

  <!-- Light brown torso -->
  <texture name="torso" type="cube" builtin="flat"
           width="128" height="128"
           rgb1="0.72 0.52 0.32" rgb2="0.72 0.52 0.32"/>
  <material name="torso" texture="torso" texuniform="true" rgba="0.72 0.52 0.32 1"/>

  <!-- Tail: slightly darker brown -->
  <texture name="tail_tex" type="cube" builtin="flat"
           width="128" height="128"
           rgb1="0.58 0.38 0.22" rgb2="0.58 0.38 0.22"/>
  <material name="tail_mat" texture="tail_tex" texuniform="true" rgba="0.58 0.38 0.22 1"/>

  <texture name="grid" type="2d" builtin="checker"
           width="512" height="512" rgb1=".1 .2 .3" rgb2=".2 .3 .4"/>
  <material name="grid" texture="grid" texrepeat="1 1"
            texuniform="true" reflectance=".2"/>
</asset>

<default>
  <motor ctrlrange="-1 1" ctrllimited="true"/>

  <default class="body">
    <geom type="capsule" condim="1" friction=".7"
          solimp=".9 .99 .003" solref=".015 1" material="body" group="1"/>
    <joint type="hinge" damping=".2" stiffness="1" armature=".01"
           limited="true" solimplimit="0 .99 .01"/>

    <default class="thigh">
      <geom fromto="0 0 0  0 0 -.3" size=".055"/>
    </default>
    <default class="shin1">
      <geom fromto="0 0 0  0 0 -.4" size=".049"/>
    </default>
    <default class="shin2">
      <geom fromto="0 0 0  0 0 -.15" size=".049" material="dark"/>
    </default>

    <default class="hip">
      <joint pos="0 0 0" axis="0 1 0" range="-60 90"
             damping=".3" stiffness="2"/>
    </default>
    <default class="knee">
      <joint pos="0 0 .02" axis="0 1 0" range="-160 2"/>
    </default>
    <default class="mid_shin">
      <joint pos="0 0 0" axis="0 1 0" range="-30 30"
             damping=".2" stiffness="2"/>
    </default>
    <default class="ankle">
      <joint range="-90 90"/>
      <default class="ankle_y">
        <joint pos="0 0 .08" axis="0 1 0" stiffness="6"/>
      </default>
      <default class="ankle_x">
        <joint pos="0 0 .04" stiffness="3"/>
      </default>
    </default>
  </default>

  <default class="foot1">
    <geom type="capsule" size=".027" fromto="-.07 -.01 0  .14 -.1 0"
          material="dark" condim="1" friction=".7"
          solimp=".9 .99 .003" solref=".015 1" group="1"/>
  </default>
  <default class="foot2">
    <geom type="capsule" size=".027" fromto="-.07 .00 0  .14 .00 0"
          material="dark" condim="1" friction=".7"
          solimp=".9 .99 .003" solref=".015 1" group="0"/>
  </default>
  <default class="foot3">
    <geom type="capsule" size=".027" fromto="-.07 .01 0  .14 .1 0"
          material="dark" condim="1" friction=".7"
          solimp=".9 .99 .003" solref=".015 1" group="1"/>
  </default>
</default>

<worldbody>
  <geom name="floor" size="0 0 .05" type="plane" material="grid" condim="3"/>
  <light name="top" pos="0 0 3" dir="0 0 -1" diffuse=".9 .9 .9"/>

  <!--
    Torso box: half-extents size="0.5 0.1 0.1" → full dims 1.0 x 0.2 x 0.2
    Fixed in space (no joint on torso).
    X axis runs front-to-back: front = +0.5, back = -0.5

    Tail attaches at the back face (x = -0.5).
    Tail box half-extents: size="0.35 0.1 0.025" → full dims 0.7 x 0.2 x 0.05
    Tail joint axis="0 1 0" → flaps up and down (rotation around Y).

    Leg hip attachment: x=0 (midpoint), y=±0.1 (sides)
  -->
  <body name="torso" pos="0 0 1.1">
    <geom name="torso_geom" type="box" size="0.5 0.1 0.1"
          material="torso" condim="3" friction=".7"/>

    <!-- ── TAIL ──
         Attached at back face of torso: pos="-0.5 0 0"
         The tail box extends further back from there (-X direction).
         Joint allows up/down flap (axis Y), range ±60°.
         The geom is offset so it hangs off the back:
         pos="-0.35 0 0" = places the tail centre 35cm behind the pivot.
    -->
    <body name="tail" pos="-0.5 0 0">
      <joint name="tail_joint"
             type="hinge"
             axis="0 1 0"
             range="-60 60"
             damping=".3"
             stiffness="3"
             armature=".01"/>
      <geom name="tail_geom"
            type="box"
            size="0.35 0.1 0.025"
            pos="-0.35 0 0"
            material="tail_mat"
            condim="3" friction=".7"/>
    </body><!-- end tail -->

    <!-- ── RIGHT LEG (y = +0.1) ── -->
    <body name="thigh_right" pos="0 0.1 0" childclass="body">
      <joint name="hip_right" class="hip"/>
      <geom  name="thigh_right" class="thigh"/>

      <body name="shin1_right" pos="0 0 -.3">
        <joint name="knee_right" class="knee"/>
        <geom  name="shin1_right" class="shin1"/>

        <body name="shin2_right" pos="0 0 -.4">
          <joint name="mid_shin_right" class="mid_shin"/>
          <geom  name="shin2_right" class="shin2"/>

          <body name="foot_right" pos="0 0 -.15">
            <joint name="ankle_y_right" class="ankle_y"/>
            <joint name="ankle_x_right" class="ankle_x" axis="1 0 .5"/>
            <geom  name="foot1_right" class="foot1"/>
            <geom  name="foot2_right" class="foot2"/>
            <geom  name="foot3_right" class="foot3"/>
          </body>
        </body>
      </body>
    </body><!-- end right leg -->

    <!-- ── LEFT LEG (y = -0.1) ── -->
    <body name="thigh_left" pos="0 -0.1 0" childclass="body">
      <joint name="hip_left" class="hip"/>
      <geom  name="thigh_left" class="thigh"/>

      <body name="shin1_left" pos="0 0 -.3">
        <joint name="knee_left" class="knee"/>
        <geom  name="shin1_left" class="shin1"/>

        <body name="shin2_left" pos="0 0 -.4">
          <joint name="mid_shin_left" class="mid_shin"/>
          <geom  name="shin2_left" class="shin2"/>

          <body name="foot_left" pos="0 0 -.15">
            <joint name="ankle_y_left" class="ankle_y"/>
            <joint name="ankle_x_left" class="ankle_x" axis="1 0 .5"/>
            <geom  name="foot1_left" class="foot1"/>
            <geom  name="foot2_left" class="foot2"/>
            <geom  name="foot3_left" class="foot3"/>
          </body>
        </body>
      </body>
    </body><!-- end left leg -->

  </body><!-- end torso -->
</worldbody>

<actuator>
  <!-- TAIL -->
  <motor name="tail"           gear="10"  joint="tail_joint"/>

  <!-- RIGHT LEG: hip | knee | mid_shin | ankle_y | ankle_x -->
  <motor name="hip_right"      gear="120" joint="hip_right"/>
  <motor name="knee_right"     gear="80"  joint="knee_right"/>
  <motor name="mid_shin_right" gear="40"  joint="mid_shin_right"/>
  <motor name="ankle_y_right"  gear="20"  joint="ankle_y_right"/>
  <motor name="ankle_x_right"  gear="20"  joint="ankle_x_right"/>

  <!-- LEFT LEG: hip | knee | mid_shin | ankle_y | ankle_x -->
  <motor name="hip_left"       gear="120" joint="hip_left"/>
  <motor name="knee_left"      gear="80"  joint="knee_left"/>
  <motor name="mid_shin_left"  gear="40"  joint="mid_shin_left"/>
  <motor name="ankle_y_left"   gear="20"  joint="ankle_y_left"/>
  <motor name="ankle_x_left"   gear="20"  joint="ankle_x_left"/>
</actuator>

<keyframe>
  <!-- 11 joints: tail | R_hip R_knee R_mid R_ank_y R_ank_x | L_hip L_knee L_mid L_ank_y L_ank_x -->
  <key name="stand" qpos="0  0 0 0 0 0  0 0 0 0 0"/>
</keyframe>

</mujoco>