<mujoco model="lower_right_leg">
<option timestep="0.005"/>

<!-- ======================================================
     ASSETS
======================================================= -->
<asset>
  <texture name="body" type="cube" builtin="flat" mark="cross"
           width="128" height="128"
           rgb1="0.8 0.6 0.4" rgb2="0.8 0.6 0.4" markrgb="1 1 1"/>
  <material name="body" texture="body" texuniform="true" rgba="0.8 0.6 .4 1"/>

  <texture name="grid" type="2d" builtin="checker"
           width="512" height="512" rgb1=".1 .2 .3" rgb2=".2 .3 .4"/>
  <material name="grid" texture="grid" texrepeat="1 1"
            texuniform="true" reflectance=".2"/>
</asset>

<!-- ======================================================
     DEFAULTS  (must come before worldbody)
======================================================= -->
<default>
  <motor ctrlrange="-1 1" ctrllimited="true"/>

  <default class="body">
    <geom type="capsule" condim="1" friction=".7"
          solimp=".9 .99 .003" solref=".015 1" material="body" group="1"/>
    <joint type="hinge" damping=".2" stiffness="1" armature=".01"
           limited="true" solimplimit="0 .99 .01"/>

    <default class="thigh">
      <geom fromto="0 0 0  0 0 -.4" size=".055"/>
    </default>

    <default class="shin">
      <geom fromto="0 0 0  0 0 -.3" size=".049"/>
    </default>

    <default class="hip">
      <joint pos="0 0 0" axis="0 1 0" range="-60 90"
             damping=".3" stiffness="2"/>
    </default>

    <default class="knee">
      <joint pos="0 0 .02" axis="0 -1 0" range="-160 2"/>
    </default>

    <default class="ankle">
      <joint range="-90 90"/>
      <default class="ankle_y">
        <joint pos="0 0 .08" axis="0 1 0" stiffness="6"/>
      </default>
      <default class="ankle_x">
        <joint pos="0 0 .04" stiffness="3"/>
      </default>
    </default>
  </default>

  <default class="foot1">
    <geom type="capsule" size=".027" fromto="-.07 -.01 0  .14 -.1 0"
          material="body" condim="1" friction=".7"
          solimp=".9 .99 .003" solref=".015 1" group="1"/>
  </default>
  <default class="foot2">
    <geom type="capsule" size=".027" fromto="-.07 .00 0  .14 .00 0"
          material="body" condim="1" friction=".7"
          solimp=".9 .99 .003" solref=".015 1" group="0"/>
  </default>
  <default class="foot3">
    <geom type="capsule" size=".027" fromto="-.07 .01 0  .14 .1 0"
          material="body" condim="1" friction=".7"
          solimp=".9 .99 .003" solref=".015 1" group="1"/>
  </default>
</default>

<!-- ======================================================
     WORLDBODY
======================================================= -->
<worldbody>
  <geom name="floor" size="0 0 .05" type="plane"
        material="grid" condim="3"/>
  <light name="top" pos="0 0 3" dir="0 0 -1" diffuse=".9 .9 .9"/>

  <!-- Anchor at hip height: 1.1m = 40cm thigh + 30cm shin + ~40cm clearance -->
  <body name="anchor" pos="0 0 1.1" childclass="body">

    <body name="thigh_right" pos="0 .01 0">
      <joint name="hip_right"   class="hip"/>
      <geom  name="thigh_right" class="thigh"/>

      <!-- Knee is at the bottom of the thigh, 40cm down -->
      <body name="shin_right" pos="0 0 -.4">
        <joint name="knee_right"   class="knee"/>
        <geom  name="shin_right"   class="shin"/>

        <!-- Ankle is 39cm below the knee -->
        <body name="foot_right" pos="0 0 -.39">
          <joint name="ankle_y_right" class="ankle_y"/>
          <joint name="ankle_x_right" class="ankle_x" axis="1 0 .5"/>
          <geom  name="foot1_right"   class="foot1"/>
          <geom  name="foot2_right"   class="foot2"/>
          <geom  name="foot3_right"   class="foot3"/>
        </body><!-- end foot_right -->

      </body><!-- end shin_right -->
    </body><!-- end thigh_right -->

  </body><!-- end anchor -->
</worldbody>

<!-- ======================================================
     ACTUATORS
     qpos / ctrl order: hip, knee, ankle_y, ankle_x
======================================================= -->
<actuator>
  <motor name="hip_right"     gear="120" joint="hip_right"/>
  <motor name="knee_right"    gear="80"  joint="knee_right"/>
  <motor name="ankle_y_right" gear="20"  joint="ankle_y_right"/>
  <motor name="ankle_x_right" gear="20"  joint="ankle_x_right"/>
</actuator>

<!-- ======================================================
     KEYFRAME
     qpos order: hip_right | knee_right | ankle_y | ankle_x
======================================================= -->
<keyframe>
  <key name="stand" qpos="0 0 0 0"/>
</keyframe>

</mujoco>